Workbook

Sheet Project Overview
A1: Foodmandu Website Manual Testing Project
A3: Field | B3: Details
A4: Project | B4: Manual QA Testing of Foodmandu Web Application
A5: Target Website | B5: https://foodmandu.com/
A6: Project Type | B6: Portfolio-ready black-box manual testing project
A7: Last Updated | B7: 2026-08-21
A8: Primary Goal | B8: Validate critical customer journeys, usability, input validation, content consistency, and order-related flows without submitting unauthorized real orders.
A9: Test Approach | B9: Functional, UI, validation, negative, boundary, exploratory, compatibility, accessibility smoke, and basic security-oriented black-box checks.
A10: Execution Status | B10: Execution reviewed: 89 Pass, 2 Fail, 1 N/A, 0 Not Executed. Two Medium-severity defects are open. Pass rate across applicable executed tests: 97.8%.
A14: Scope
A15: In Scope | B15: Home page; restaurant/cuisine search; restaurant listing; filters/sorting; restaurant detail/menu; food-item search; authentication; registration; forgot password; cart; delivery details; order review; delivery charges; help/footer content; responsive behavior; accessibility smoke checks.
A16: Out of Scope | B16: Admin/back-office systems; restaurant partner portal; destructive testing; load testing; payment capture; placing real paid orders; social-login account creation without authorization.
A17: Safety Constraint | B17: Do not complete an order that creates a real charge or operational delivery unless you have explicit authorization and a disposable test account/address.
A19: Verified Public Product Notes Used for Test Design
A20: Source | B20: Verified public information
A21: https://foodmandu.com/ | B21: Homepage exposes restaurant/cuisine search, featured restaurants, login, help links, and service hours.
A22: https://foodmandu.com/Restaurant/Index | B22: Restaurant listing exposes filters, cuisine filtering, sorting, and no-results states.
A23: https://foodmandu.com/Account/Login | B23: Login supports email/password, Remember Me, Facebook, Google, Sign Up, and Forgot Password.
A24: https://foodmandu.com/Account/register | B24: Registration asks for first name, last name, email, mobile, password, confirm password, and terms agreement.
A25: https://foodmandu.com/Home/HowToOrder | B25: Official flow describes choosing a restaurant, selecting food, entering delivery details/date/time, and confirming an order.
A26: https://foodmandu.com/Home/DeliveryCharge | B26: Published delivery charge: Rs. 20 up to 1 km, then additional Rs. 20/km; Foodmandu Fresh Rs. 100/order.

Sheet Test Plan
A1: Manual Test Plan
A3: 1. Objective
A4: Verify that Foodmandu's customer-facing website supports reliable restaurant discovery, account access, menu browsing, cart/order preparation, delivery information, and supporting help content.
A6: 2. Entry Criteria
A7: Website is reachable; test browser has internet access; no major outage; test data is available; tester understands that real order submission is excluded unless authorized.
A9: 3. Exit Criteria
A10: All Critical/High-priority cases executed; no open Critical defects; major customer journeys covered; all defects recorded with reproducible steps and evidence.
A12: 4. Test Techniques
A13: Equivalence partitioning, boundary value analysis, positive/negative testing, state transition checks, exploratory testing, error guessing, usability review, and responsive UI checks.
A15: 5. Browsers / Devices
A16: Desktop: latest Chrome, Edge, Firefox. Mobile smoke: Chrome Android or responsive emulation at ~360x800 and ~390x844. Optional Safari/iOS if available.
A18: 6. Test Data
... A31: Test plan, scenarios, detailed test cases, RTM, test data, execution dashboard, exploratory charters, and defect log.

Sheet Test Scenarios
A1: Scenario ID | B1: Module | C1: Scenario | D1: Priority | E1: Test Type | F1: Coverage Goal | G1: Execution Result
A2: TS-001 | B2: Homepage | C2: Verify homepage loads and core navigation is available | D2: High | E2: Functional/UI | F2: Critical entry points | G2: =IF(COUNTIF('Test Cases'!$C$2:$C$93,A2)=0,"No Cases",IF(COUNTIFS('Test Cases'!$C$2:$C$93,A2,'Test Cases'!$K$2:$K$93,"Fail")>0,"Fail",IF(COUNTIFS('Test Cases'!$C$2:$C$93,A2,'Test Cases'!$K$2:$K$93,"Blocked")>0,"Blocked",IF(COUNTIFS('Test Cases'!$C$2:$C$93,A2,'Test Cases'!$K$2:$K$93,"Not Executed")>0,"Partial",IF(COUNTIFS('Test Cases'!$C$2:$C$93,A2,'Test Cases'!$K$2:$K$93,"N/A")>0,"Pass with N/A","Pass"))))) -> Pass
A3: TS-002 | B3: Search | C3: Verify restaurant/cuisine search with valid keywords | D3: Critical | E3: Functional | F3: Discovery | G3: =IF(COUNTIF('Test Cases'!$C$2:$C$93,A3)=0,"No Cases",IF(COUNTIFS('Test Cases'!$C$2:$C$93,A3,'Test Cases'!$K$2:$K$93,"Fail")>0,"Fail",IF(COUNTIFS('Test Cases'!$C$2:$C$93,A3,'Test Cases'!$K$2:$K$93,"Blocked")>0,"Blocked",IF(COUNTIFS('Test Cases'!$C$2:$C$93,A3,'Test Cases'!$K$2:$K$93,"Not Executed")>0,"Partial",IF(COUNTIFS('Test Cases'!$C$2:$C$93,A3,'Test Cases'!$K$2:$K$93,"N/A")>0,"Pass with N/A","Pass"))))) -> Pass
A4: TS-003 | B4: Search | C4: Verify search with invalid, empty, whitespace, and special-character input | D4: High | E4: Negative/Boundary | F4: Validation | G4: =IF(COUNTIF('Test Cases'!$C$2:$C$93,A4)=0,"No Cases",IF(COUNTIFS('Test Cases'!$C$2:$C$93,A4,'Test Cases'!$K$2:$K$93,"Fail")>0,"Fail",IF(COUNTIFS('Test Cases'!$C$2:$C$93,A4,'Test Cases'!$K$2:$K$93,"Blocked")>0,"Blocked",IF(COUNTIFS('Test Cases'!$C$2:$C$93,A4,'Test Cases'!$K$2:$K$93,"Not Executed")>0,"Partial",IF(COUNTIFS('Test Cases'!$C$2:$C$93,A4,'Test Cases'!$K$2:$K$93,"N/A")>0,"Pass with N/A","Pass"))))) -> Pass
A5: TS-004 | B5: Restaurant Listing | C5: Verify restaurant results display relevant information | D5: High | E5: Functional/UI | F5: Discovery | G5: =IF(COUNTIF('Test Cases'!$C$2:$C$93,A5)=0,"No Cases",IF(COUNTIFS('Test Cases'!$C$2:$C$93,A5,'Test Cases'!$K$2:$K$93,"Fail")>0,"Fail",IF(COUNTIFS('Test Cases'!$C$2:$C$93,A5,'Test Cases'!$K$2:$K$93,"Blocked")>0,"Blocked",IF(COUNTIFS('Test Cases'!$C$2:$C$93,A5,'Test Cases'!$K$2:$K$93,"Not Executed")>0,"Partial",IF(COUNTIFS('Test Cases'!$C$2:$C$93,A5,'Test Cases'!$K$2:$K$93,"N/A")>0,"Pass with N/A","Pass"))))) -> Pass
A6: TS-005 | B6: Restaurant Listing | C6: Verify cuisine filters and filter reset behavior | D6: High | E6: Functional | F6: Filtering | G6: =IF(COUNTIF('Test Cases'!$C$2:$C$93,A6)=0,"No Cases",IF(COUNTIFS('Test Cases'!$C$2:$C$93,A6,'Test Cases'!$K$2:$K$93,"Fail")>0,"Fail",IF(COUNTIFS('Test Cases'!$C$2:$C$93,A6,'Test Cases'!$K$2:$K$93,"Blocked")>0,"Blocked",IF(COUNTIFS('Test Cases'!$C$2:$C$93,A6,'Test Cases'!$K$2:$K$93,"Not Executed")>0,"Partial",IF(COUNTIFS('Test Cases'!$C$2:$C$93,A6,'Test Cases'!$K$2:$K$93,"N/A")>0,"Pass with N/A","Pass"))))) -> Pass
A7: TS-006 | B7: Restaurant Listing | C7: Verify sorting behavior | D7: Medium | E7: Functional | F7: Sorting | G7: =IF(COUNTIF('Test Cases'!$C$2:$C$93,A7)=0,"No Cases",IF(COUNTIFS('Test Cases'!$C$2:$C$93,A7,'Test Cases'!$K$2:$K$93,"Fail")>0,"Fail",IF(COUNTIFS('Test Cases'!$C$2:$C$93,A7,'Test Cases'!$K$2:$K$93,"Blocked")>0,"Blocked",IF(COUNTIFS('Test Cases'!$C$2:$C$93,A7,'Test Cases'!$K$2:$K$93,"Not Executed")>0,"Partial",IF(COUNTIFS('Test Cases'!$C$2:$C$93,A7,'Test Cases'!$K$2:$K$93,"N/A")>0,"Pass with N/A","Pass"))))) -> Pass
A8: TS-007 | B8: Restaurant Listing | C8: Verify no-results state | D8: Medium | E8: Negative/UI | F8: Error state | G8: =IF(COUNTIF('Test Cases'!$C$2:$C$93,A8)=0,"No Cases",IF(COUNTIFS('Test Cases'!$C$2:$C$93,A8,'Test Cases'!$K$2:$K$93,"Fail")>0,"Fail",IF(COUNTIFS('Test Cases'!$C$2:$C$93,A8,'Test Cases'!$K$2:$K$93,"Blocked")>0,"Blocked",IF(COUNTIFS('Test Cases'!$C$2:$C$93,A8,'Test Cases'!$K$2:$K$93,"Not Executed")>0,"Partial",IF(COUNTIFS('Test Cases'!$C$2:$C$93,A8,'Test Cases'!$K$2:$K$93,"N/A")>0,"Pass with N/A","Pass"))))) -> Pass
A9: TS-008 | B9: Restaurant Detail | C9: Verify restaurant detail, delivery hours, fees, and menu information | D9: Critical | E9: Functional/UI | F9: Restaurant selection | G9: =IF(COUNTIF('Test Cases'!$C$2:$C$93,A9)=0,"No Cases",IF(COUNTIFS('Test Cases'!$C$2:$C$93,A9,'Test Cases'!$K$2:$K$93,"Fail")>0,"Fail",IF(COUNTIFS('Test Cases'!$C$2:$C$93,A9,'Test Cases'!$K$2:$K$93,"Blocked")>0,"Blocked",IF(COUNTIFS('Test Cases'!$C$2:$C$93,A9,'Test Cases'!$K$2:$K$93,"Not Executed")>0,"Partial",IF(COUNTIFS('Test Cases'!$C$2:$C$93,A9,'Test Cases'!$K$2:$K$93,"N/A")>0,"Pass with N/A","Pass"))))) -> Fail
A10: TS-009 | B10: Menu | C10: Verify menu category navigation and food-item search | D10: High | E10: Functional | F10: Menu discovery | G10: =IF(COUNTIF('Test Cases'!$C$2:$C$93,A10)=0,"No Cases",IF(COUNTIFS('Test Cases'!$C$2:$C$93,A10,'Test Cases'!$K$2:$K$93,"Fail")>0,"Fail",IF(COUNTIFS('Test Cases'!$C$2:$C$93,A10,'Test Cases'!$K$2:$K$93,"Blocked")>0,"Blocked",IF(COUNTIFS('Test Cases'!$C$2:$C$93,A10,'Test Cases'!$K$2:$K$93,"Not Executed")>0,"Partial",IF(COUNTIFS('Test Cases'!$C$2:$C$93,A10,'Test Cases'!$K$2:$K$93,"N/A")>0,"Pass with N/A","Pass"))))) -> Pass
A11: TS-010 | B11: Cart | C11: Verify adding a food item to cart | D11: Critical | E11: Functional | F11: Cart creation | G11: =IF(COUNTIF('Test Cases'!$C$2:$C$93,A11)=0,"No Cases",IF(COUNTIFS('Test Cases'!$C$2:$C$93,A11,'Test Cases'!$K$2:$K$93,"Fail")>0,"Fail",IF(COUNTIFS('Test Cases'!$C$2:$C$93,A11,'Test Cases'!$K$2:$K$93,"Blocked")>0,"Blocked",IF(COUNTIFS('Test Cases'!$C$2:$C$93,A11,'Test Cases'!$K$2:$K$93,"Not Executed")>0,"Partial",IF(COUNTIFS('Test Cases'!$C$2:$C$93,A11,'Test Cases'!$K$2:$K$93,"N/A")>0,"Pass with N/A","Pass"))))) -> Pass
A12: TS-011 | B12: Cart | C12: Verify quantity update and removal | D12: Critical | E12: Functional | F12: Cart management | G12: =IF(COUNTIF('Test Cases'!$C$2:$C$93,A12)=0,"No Cases",IF(COUNTIFS('Test Cases'!$C$2:$C$93,A12,'Test Cases'!$K$2:$K$93,"Fail")>0,"Fail",IF(COUNTIFS('Test Cases'!$C$2:$C$93,A12,'Test Cases'!$K$2:$K$93,"Blocked")>0,"Blocked",IF(COUNTIFS('Test Cases'!$C$2:$C$93,A12,'Test Cases'!$K$2:$K$93,"Not Executed")>0,"Partial",IF(COUNTIFS('Test Cases'!$C$2:$C$93,A12,'Test Cases'!$K$2:$K$93,"N/A")>0,"Pass with N/A","Pass"))))) -> Pass
A13: TS-012 | B13: Cart | C13: Verify price calculations and totals | D13: Critical | E13: Functional/Data | F13: Commerce accuracy | G13: =IF(COUNTIF('Test Cases'!$C$2:$C$93,A13)=0,"No Cases",IF(COUNTIFS('Test Cases'!$C$2:$C$93,A13,'Test Cases'!$K$2:$K$93,"Fail")>0,"Fail",IF(COUNTIFS('Test Cases'!$C$2:$C$93,A13,'Test Cases'!$K$2:$K$93,"Blocked")>0,"Blocked",IF(COUNTIFS('Test Cases'!$C$2:$C$93,A13,'Test Cases'!$K$2:$K$93,"Not Executed")>0,"Partial",IF(COUNTIFS('Test Cases'!$C$2:$C$93,A13,'Test Cases'!$K$2:$K$93,"N/A")>0,"Pass with N/A","Pass"))))) -> Pass
... A25: TS-024 | B25: External Auth | C25: Verify Google/Facebook auth entry points open correctly without completing unauthorized signup | D25: Medium | E25: Integration | F25: External auth | G25: =IF(COUNTIF('Test Cases'!$C$2:$C$93,A25)=0,"No Cases",IF(COUNTIFS('Test Cases'!$C$2:$C$93,A25,'Test Cases'!$K$2:$K$93,"Fail")>0,"Fail",IF(COUNTIFS('Test Cases'!$C$2:$C$93,A25,'Test Cases'!$K$2:$K$93,"Blocked")>0,"Blocked",IF(COUNTIFS('Test Cases'!$C$2:$C$93,A25,'Test Cases'!$K$2:$K$93,"Not Executed")>0,"Partial",IF(COUNTIFS('Test Cases'!$C$2:$C$93,A25,'Test Cases'!$K$2:$K$93,"N/A")>0,"Pass with N/A","Pass"))))) -> Pass
A26: TS-025 | B26: Exploratory | C26: Explore customer journey from search to pre-confirmation checkout | D26: Critical | E26: Exploratory | F26: End-to-end risk discovery | G26: Charter Only

Sheet Test Cases
A1: TC ID | B1: Module | C1: Scenario ID | D1: Test Case | E1: Preconditions | F1: Steps | G1: Test Data | H1: Expected Result | I1: Priority | J1: Type | K1: Status | L1: Actual Result | M1: Defect ID | N1: Notes
A2: TC-001 | B2: Homepage | C2: TS-001 | D2: Open Foodmandu homepage | E2: Internet available | F2: 1. Navigate to https://foodmandu.com/ 2. Observe page load | G2: N/A | H2: Homepage loads without fatal error; branding, search, featured restaurants, Login and footer/help links are available. | I2: Critical | J2: Smoke | K2: Pass | L2: Observed behavior matched the expected result.
A3: TC-002 | B3: Homepage | C3: TS-001 | D3: Verify restaurant/cuisine search input is visible | E3: Homepage loaded | F3: Locate main search control | G3: N/A | H3: Search field and Find Restaurants action are visible and usable. | I3: High | J3: UI | K3: Pass | L3: Observed behavior matched the expected result.
A4: TC-003 | B4: Homepage | C4: TS-001 | D4: Open a featured restaurant | E4: Homepage loaded | F4: Select one featured restaurant card | G4: Any visible featured restaurant | H4: Restaurant detail page opens for the selected restaurant. | I4: High | J4: Navigation | K4: Pass | L4: Observed behavior matched the expected result.
A5: TC-004 | B5: Homepage | C5: TS-001 | D5: Verify footer help links | E5: Homepage loaded | F5: Open About Us, Delivery Charges, How to Order, FAQs, Contact, Terms, Privacy one by one | G5: N/A | H5: Each link routes to the intended page without 404/error. | I5: Medium | J5: Navigation | K5: Pass | L5: Observed behavior matched the expected result.
A6: TC-005 | B6: Homepage | C6: TS-001 | D6: Verify service hours display | E6: Homepage loaded | F6: Scroll to footer and read service hours | G6: N/A | H6: Service hours are displayed consistently and legibly. | I6: Low | J6: Content | K6: Pass | L6: Observed behavior matched the expected result.
A7: TC-006 | B7: Search | C7: TS-002 | D7: Search by restaurant name | E7: Homepage loaded | F7: Enter known restaurant name; submit search | G7: Fire And Ice | H7: Relevant matching restaurant(s) appear. | I7: Critical | J7: Functional | K7: Pass | L7: Observed behavior matched the expected result.
A8: TC-007 | B8: Search | C8: TS-002 | D8: Search by cuisine | E8: Homepage loaded | F8: Enter cuisine keyword; submit | G8: Pizza | H8: Results include restaurants/products relevant to pizza. | I8: High | J8: Functional | K8: Pass | L8: Observed behavior matched the expected result.
A9: TC-008 | B9: Search | C9: TS-002 | D9: Search is case-insensitive | E9: Homepage loaded | F9: Search same keyword using different casing | G9: pizza / PIZZA | H9: Results are logically equivalent or search handles casing gracefully. | I9: Medium | J9: Functional | K9: Pass | L9: Observed behavior matched the expected result.
A10: TC-009 | B10: Search | C10: TS-003 | D10: Search with empty input | E10: Homepage loaded | F10: Leave search empty; submit | G10: Blank | H10: System prevents meaningless search or returns a sensible default/list without error. | I10: Medium | J10: Negative | K10: Pass | L10: Observed behavior matched the expected result.
A11: TC-010 | B11: Search | C11: TS-003 | D11: Search with spaces only | E11: Homepage loaded | F11: Enter spaces; submit | G11: 238 | H11: Whitespace is trimmed or handled without crash. | I11: Medium | J11: Negative | K11: Pass | L11: Observed behavior matched the expected result.
A12: TC-011 | B12: Search | C12: TS-003 | D12: Search with special characters | E12: Homepage loaded | F12: Enter special characters; submit | G12: @#$%^ | H12: No script/error leakage; safe no-results or sanitized behavior. | I12: High | J12: Security/Negative | K12: Pass | L12: Observed behavior matched the expected result.
A13: TC-012 | B13: Search | C13: TS-003 | D13: Search with long input | E13: Homepage loaded | F13: Paste a 250-character query; submit | G13: 250-char string | H13: UI remains stable; input is bounded/handled; no server error. | I13: Medium | J13: Boundary | K13: Pass | L13: Observed behavior matched the expected result.
... A22: TC-021 | B22: Restaurant Detail | C22: TS-008 | D22: Verify restaurant delivery hours | E22: Restaurant page loaded | F22: Inspect delivery hours summary and weekly hours | G22: N/A | H22: Hours are displayed clearly and do not contradict within the same page. | I22: High | J22: Content | K22: Pass | L22: Observed behavior matched the expected result.
A23: TC-022 | B23: Restaurant Detail | C23: TS-008 | D23: Verify minimum order format | E23: Restaurant page loaded | F23: Inspect minimum-order field | G23: N/A | H23: A valid currency value or clear 'No minimum' message is shown; malformed values such as 'Rs. .00' are not shown. | I23: Medium | J23: Data/UI | K23: Fail | L23: Minimum order was displayed as 'Rs. .00', which is a malformed currency value. | M23: BUG-001 | N23: Confirmed during manual execution. See BUG-001 in Defect Log.
A24: TC-023 | B24: Restaurant Detail | C24: TS-008 | D24: Verify service charge and VAT labels | E24: Restaurant page loaded | F24: Inspect service charge and VAT values | G24: N/A | H24: Each displays a valid percentage/value or clear N/A consistently. | I24: Medium | J24: Data/UI | K24: Pass | L24: Observed behavior matched the expected result.
A25: TC-024 | B25: Menu | C25: TS-009 | D25: Search food items within restaurant | E25: Restaurant page loaded | F25: Use Search Food Items with known menu keyword | G25: Pizza | H25: Matching menu items are filtered/displayed. | I25: High | J25: Functional | K25: Pass | L25: Observed behavior matched the expected result.
A26: TC-025 | B26: Menu | C26: TS-009 | D26: Food-item search no-results state | E26: Restaurant page loaded | F26: Search a non-existent item | G26: zzzz123 | H26: Clear no-results feedback; no crash. | I26: Medium | J26: Negative | K26: Pass | L26: Observed behavior matched the expected result.
A27: TC-026 | B27: Menu | C27: TS-009 | D27: Navigate menu categories | E27: Restaurant page with categories loaded | F27: Select category/subcategory | G27: Any available category | H27: Menu moves/filters to chosen category correctly. | I27: High | J27: Functional | K27: Pass | L27: Observed behavior matched the expected result.
A28: TC-027 | B28: Restaurant Detail | C28: TS-008 | D28: Verify item price presentation | E28: Restaurant page loaded | F28: Inspect several food items | G28: N/A | H28: Prices use consistent NPR/Rs. formatting and no raw template placeholders are visible. | I28: Critical | J28: Data/UI | K28: Pass | L28: Observed behavior matched the expected result.
A29: TC-028 | B29: Restaurant Detail | C29: TS-008 | D29: Verify restaurant close state | E29: Open a closed restaurant if available | F29: Inspect ordering controls | G29: Closed restaurant | H29: Closed status is clear; ordering unavailable or appropriately constrained. | I29: High | J29: State Transition | K29: Pass | L29: Observed behavior matched the expected result.
A30: TC-029 | B30: Restaurant Detail | C30: TS-008 | D30: Verify branch links | E30: Restaurant with branches if available | F30: Open another branch | G30: N/A | H30: Correct branch restaurant page opens; branch identity is clear. | I30: Low | J30: Navigation | K30: Pass | L30: Observed behavior matched the expected result.
A31: TC-030 | B31: Cart | C31: TS-010 | D31: Add one available food item to cart | E31: Open restaurant; item available | F31: Click Add/plus action for one item | G31: 1 menu item | H31: Cart is created and selected item appears with correct name, price, quantity. | I31: Critical | J31: Functional | K31: Pass | L31: Observed behavior matched the expected result.
A32: TC-031 | B32: Cart | C32: TS-010 | D32: Add multiple different items | E32: Cart has one item | F32: Add two different items | G32: 3 distinct items | H32: All items appear without duplication/corruption. | I32: Critical | J32: Functional | K32: Pass | L32: Observed behavior matched the expected result.
A33: TC-032 | B33: Cart | C33: TS-011 | D33: Increase item quantity | E33: Cart contains item | F33: Increase quantity once | G33: Qty 1 -> 2 | H33: Quantity becomes 2 and line subtotal updates. | I33: Critical | J33: Functional | K33: Pass | L33: Observed behavior matched the expected result.
A34: TC-033 | B34: Cart | C34: TS-011 | D34: Decrease item quantity | E34: Item quantity > 1 | F34: Decrease quantity | G34: Qty 2 -> 1 | H34: Quantity decreases and totals update. | I34: Critical | J34: Functional | K34: Pass | L34: Observed behavior matched the expected result.
A35: TC-034 | B35: Cart | C35: TS-011 | D35: Remove item from cart | E35: Cart contains item | F35: Use remove/delete action | G35: N/A | H35: Item is removed and total recalculates. | I35: Critical | J35: Functional | K35: Pass | L35: Observed behavior matched the expected result.
... A71: TC-070 | B71: Checkout | C71: TS-017 | D71: Review customer delivery details | E71: Checkout/pre-confirmation loaded | F71: Compare displayed details with entered values | G71: N/A | H71: Address/contact/time are accurate before confirmation. | I71: Critical | J71: Data | K71: Pass | L71: Observed behavior matched the expected result.
A72: TC-071 | B72: Checkout | C72: TS-017 | D72: Prevent accidental duplicate final submission | E72: Authorized test environment only; otherwise do not execute | F72: Double-click final confirm only in authorized non-operational environment | G72: N/A | H72: System prevents duplicate order creation or provides safe idempotent behavior. | I72: Critical | J72: Reliability | K72: N/A | L72: Not executed on the live production website because the test requires an authorized non-operational environment. | N72: Not executed against the live operational website. This reliability test requires an authorized non-operational environment.
A73: TC-072 | B73: Delivery | C73: TS-018 | D73: Verify delivery charge page values | E73: Delivery Charge page loaded | F73: Read published rule | G73: Up to 1 km Rs.20; after 1 km +Rs.20/km | H73: Rules are visible and unambiguous. | I73: High | J73: Content | K73: Pass | L73: Observed behavior matched the expected result.
A74: TC-073 | B74: Delivery | C74: TS-018 | D74: Verify Foodmandu Fresh charge | E74: Delivery Charge page loaded | F74: Read Fresh charge | G74: Rs.100/order | H74: Fresh delivery charge is displayed clearly. | I74: Medium | J74: Content | K74: Pass | L74: Observed behavior matched the expected result.
A75: TC-074 | B75: Delivery | C75: TS-018 | D75: Verify checkout fee matches published rule where testable | E75: Checkout estimates delivery fee | F75: Compare displayed fee with distance/rule if data permits | G75: Known test address | H75: Fee presentation is consistent with published policy or explains exceptions. | I75: Critical | J75: Business Rule | K75: Pass | L75: Observed behavior matched the expected result.
A76: TC-075 | B76: Delivery | C76: TS-018 | D76: Verify currency formatting | E76: Delivery page/checkout loaded | F76: Inspect fee values | G76: N/A | H76: NPR/Rs. values are consistently formatted; no malformed decimal values. | I76: Medium | J76: UI/Data | K76: Pass | L76: Observed behavior matched the expected result.
A77: TC-076 | B77: Help & Content | C77: TS-019 | D77: How to Order content opens | E77: Homepage/footer available | F77: Open How to Order | G77: N/A | H77: Instructions page loads and describes current ordering process clearly. | I77: Medium | J77: Content | K77: Pass | L77: Observed behavior matched the expected result.
A78: TC-077 | B78: Help & Content | C78: TS-019 | D78: FAQ content renders | E78: Homepage/footer available | F78: Open FAQs | G78: N/A | H78: FAQ questions/answers render; raw template placeholders are not visible. | I78: Medium | J78: Content/UI | K78: Pass | L78: Observed behavior matched the expected result.
A79: TC-078 | B79: Help & Content | C79: TS-019 | D79: Contact page opens | E79: Homepage/footer available | F79: Open Contact Us | G79: N/A | H79: Contact information/form content loads without error. | I79: Medium | J79: Navigation | K79: Pass | L79: Observed behavior matched the expected result.
A80: TC-079 | B80: Help & Content | C80: TS-019 | D80: Terms page content is current | E80: Terms page loaded | F80: Review ordering/payment statements and footer date | G80: N/A | H80: Legal/content statements do not materially contradict current product behavior and dated content is maintained appropriately. | I80: Medium | J80: Content | K80: Fail | L80: Terms content was marked inconsistent with the current product behavior during execution; the payment wording appears outdated. | M80: BUG-002 | N80: Confirmed during manual execution. See BUG-002. The separate footer-year observation remains pending verification.
A81: TC-080 | B81: Help & Content | C81: TS-019 | D81: Privacy Policy link opens | E81: Footer loaded | F81: Open Privacy Policy | G81: N/A | H81: Privacy page opens over HTTPS. | I81: High | J81: Navigation | K81: Pass | L81: Observed behavior matched the expected result.
A82: TC-081 | B82: Help & Content | C82: TS-019 | D82: Broken-link smoke test | E82: Public pages loaded | F82: Open major header/footer/internal links manually | G82: N/A | H82: No critical navigation link returns 404/500 or dead end. | I82: High | J82: Navigation | K82: Pass | L82: Observed behavior matched the expected result.
A83: TC-082 | B83: Responsive UI | C83: TS-020 | D83: Homepage at 360px width | E83: Browser responsive mode | F83: Set viewport ~360x800; inspect header/search/cards/footer | G83: 360x800 | H83: No horizontal overflow or unusable overlapping controls. | I83: High | J83: Responsive | K83: Pass | L83: Observed behavior matched the expected result.
...

Sheet Defect Log
A1: Defect ID | B1: Linked Test Case | C1: Title | D1: Module | E1: Severity | F1: Priority | G1: Status | H1: Environment / Evidence | I1: Steps to Reproduce | J1: Expected Result | K1: Actual Result | L1: Source URL | M1: Notes
A2: BUG-001 | B2: TC-022 | C2: Minimum order value is malformed as 'Rs. .00' | D2: Restaurant Detail | E2: Medium | F2: P2 | G2: Open | H2: Manual browser execution reviewed 2026-08-21; original public-page observation 2026-08-19 | I2: 1. Open the affected restaurant detail page. 2. Inspect the Minimum order value. | J2: Display a valid currency amount such as Rs. 0.00, or a clear 'No minimum order' message. | K2: Minimum order is displayed as 'Rs. .00'. | L2: https://foodmandu.com/Restaurant/Details/1027 | M2: Confirmed by failed test case TC-022.
A3: BUG-002 | B3: TC-079 | C3: Terms page payment statement appears outdated | D3: Help & Content | E3: Medium | F3: P2 | G3: Open | H3: Manual browser execution reviewed 2026-08-21; original terms-page observation 2026-08-19 | I3: 1. Open Terms of Usage. 2. Review the ORDERING AND PAYMENT section. 3. Compare it with the current product behavior observed during testing. | J3: Legal and payment information should accurately describe the current customer ordering/payment experience. | K3: The payment wording on the Terms page was marked inconsistent with current product behavior during TC-079 execution. | L3: https://foodmandu.com/Home/TermsOfUse | M3: Confirmed through failed TC-079. Before external submission, quote the exact current wording and attach a browser screenshot.
A4: OBS-002 | B4: TC-079 | C4: Footer copyright year shows 2025 on current public output | D4: Help & Content | E4: Low | F4: P3 | G4: Open | H4: Public-page observation 2026-08-19 | I4: 1. Open the homepage or Terms page. 2. Scroll to the footer. 3. Check the copyright year. | J4: If the site intends a current-year copyright display, it should show 2026 or a maintained year range. | K4: Public output showed © 2025 Foodmandu Pvt. Ltd.; explicit browser confirmation was not recorded. | L4: https://foodmandu.com/ | M4: Keep as an observation until manually confirmed in the browser. It may be intentional.

Sheet RTM
A1: Requirement ID | B1: Requirement / User Need | C1: Primary Scenario | D1: Mapped Test Cases | E1: Priority | F1: Coverage Status
A2: REQ-001 | B2: User can discover restaurants from the homepage | C2: TS-001 | D2: TC-001 to TC-005 | E2: Critical | F2: =IF(COUNTIF('Test Cases'!K2:K6,"Fail")>0,"Executed - Fail",IF(COUNTIF('Test Cases'!K2:K6,"Blocked")>0,"Executed - Blocked",IF(COUNTIF('Test Cases'!K2:K6,"Not Executed")>0,"Partially Executed",IF(COUNTIF('Test Cases'!K2:K6,"N/A")>0,"Executed - Pass with N/A","Executed - Pass")))) -> Executed - Pass
A3: REQ-002 | B3: User can search by restaurant or cuisine | C3: TS-002/003 | D3: TC-006 to TC-013 | E3: Critical | F3: =IF(COUNTIF('Test Cases'!K7:K14,"Fail")>0,"Executed - Fail",IF(COUNTIF('Test Cases'!K7:K14,"Blocked")>0,"Executed - Blocked",IF(COUNTIF('Test Cases'!K7:K14,"Not Executed")>0,"Partially Executed",IF(COUNTIF('Test Cases'!K7:K14,"N/A")>0,"Executed - Pass with N/A","Executed - Pass")))) -> Executed - Pass
A4: REQ-003 | B4: User can filter/sort restaurant results | C4: TS-004 to TS-007 | D4: TC-014 to TC-020 | E4: High | F4: =IF(COUNTIF('Test Cases'!K15:K21,"Fail")>0,"Executed - Fail",IF(COUNTIF('Test Cases'!K15:K21,"Blocked")>0,"Executed - Blocked",IF(COUNTIF('Test Cases'!K15:K21,"Not Executed")>0,"Partially Executed",IF(COUNTIF('Test Cases'!K15:K21,"N/A")>0,"Executed - Pass with N/A","Executed - Pass")))) -> Executed - Pass
A5: REQ-004 | B5: User can view restaurant details and menu | C5: TS-008/009 | D5: TC-021 to TC-029 | E5: Critical | F5: =IF(COUNTIF('Test Cases'!K22:K30,"Fail")>0,"Executed - Fail",IF(COUNTIF('Test Cases'!K22:K30,"Blocked")>0,"Executed - Blocked",IF(COUNTIF('Test Cases'!K22:K30,"Not Executed")>0,"Partially Executed",IF(COUNTIF('Test Cases'!K22:K30,"N/A")>0,"Executed - Pass with N/A","Executed - Pass")))) -> Executed - Fail
A6: REQ-005 | B6: User can build and manage a cart | C6: TS-010 to TS-012 | D6: TC-030 to TC-039 | E6: Critical | F6: =IF(COUNTIF('Test Cases'!K31:K40,"Fail")>0,"Executed - Fail",IF(COUNTIF('Test Cases'!K31:K40,"Blocked")>0,"Executed - Blocked",IF(COUNTIF('Test Cases'!K31:K40,"Not Executed")>0,"Partially Executed",IF(COUNTIF('Test Cases'!K31:K40,"N/A")>0,"Executed - Pass with N/A","Executed - Pass")))) -> Executed - Pass
A7: REQ-006 | B7: User can authenticate securely | C7: TS-013/023/024 | D7: TC-040 to TC-048 | E7: Critical | F7: =IF(COUNTIF('Test Cases'!K41:K49,"Fail")>0,"Executed - Fail",IF(COUNTIF('Test Cases'!K41:K49,"Blocked")>0,"Executed - Blocked",IF(COUNTIF('Test Cases'!K41:K49,"Not Executed")>0,"Partially Executed",IF(COUNTIF('Test Cases'!K41:K49,"N/A")>0,"Executed - Pass with N/A","Executed - Pass")))) -> Executed - Pass
A8: REQ-007 | B8: User can register with validated data | C8: TS-014 | D8: TC-049 to TC-057 | E8: High | F8: =IF(COUNTIF('Test Cases'!K50:K58,"Fail")>0,"Executed - Fail",IF(COUNTIF('Test Cases'!K50:K58,"Blocked")>0,"Executed - Blocked",IF(COUNTIF('Test Cases'!K50:K58,"Not Executed")>0,"Partially Executed",IF(COUNTIF('Test Cases'!K50:K58,"N/A")>0,"Executed - Pass with N/A","Executed - Pass")))) -> Executed - Pass
A9: REQ-008 | B9: User can recover forgotten password | C9: TS-015 | D9: TC-058 to TC-062 | E9: High | F9: =IF(COUNTIF('Test Cases'!K59:K63,"Fail")>0,"Executed - Fail",IF(COUNTIF('Test Cases'!K59:K63,"Blocked")>0,"Executed - Blocked",IF(COUNTIF('Test Cases'!K59:K63,"Not Executed")>0,"Partially Executed",IF(COUNTIF('Test Cases'!K59:K63,"N/A")>0,"Executed - Pass with N/A","Executed - Pass")))) -> Executed - Pass
A10: REQ-009 | B10: User can provide delivery/order details | C10: TS-016/017 | D10: TC-063 to TC-071 | E10: Critical | F10: =IF(COUNTIF('Test Cases'!K64:K72,"Fail")>0,"Executed - Fail",IF(COUNTIF('Test Cases'!K64:K72,"Blocked")>0,"Executed - Blocked",IF(COUNTIF('Test Cases'!K64:K72,"Not Executed")>0,"Partially Executed",IF(COUNTIF('Test Cases'!K64:K72,"N/A")>0,"Executed - Pass with N/A","Executed - Pass")))) -> Executed - Pass with N/A
A11: REQ-010 | B11: Delivery fees are transparent and consistent | C11: TS-018 | D11: TC-072 to TC-075 | E11: High | F11: =IF(COUNTIF('Test Cases'!K73:K76,"Fail")>0,"Executed - Fail",IF(COUNTIF('Test Cases'!K73:K76,"Blocked")>0,"Executed - Blocked",IF(COUNTIF('Test Cases'!K73:K76,"Not Executed")>0,"Partially Executed",IF(COUNTIF('Test Cases'!K73:K76,"N/A")>0,"Executed - Pass with N/A","Executed - Pass")))) -> Executed - Pass
A12: REQ-011 | B12: Help/legal/support content is accessible | C12: TS-019 | D12: TC-076 to TC-081 | E12: Medium | F12: =IF(COUNTIF('Test Cases'!K77:K82,"Fail")>0,"Executed - Fail",IF(COUNTIF('Test Cases'!K77:K82,"Blocked")>0,"Executed - Blocked",IF(COUNTIF('Test Cases'!K77:K82,"Not Executed")>0,"Partially Executed",IF(COUNTIF('Test Cases'!K77:K82,"N/A")>0,"Executed - Pass with N/A","Executed - Pass")))) -> Executed - Fail
A13: REQ-012 | B13: Core flows are usable on mobile and desktop | C13: TS-020 | D13: TC-082 to TC-085 | E13: High | F13: =IF(COUNTIF('Test Cases'!K83:K86,"Fail")>0,"Executed - Fail",IF(COUNTIF('Test Cases'!K83:K86,"Blocked")>0,"Executed - Blocked",IF(COUNTIF('Test Cases'!K83:K86,"Not Executed")>0,"Partially Executed",IF(COUNTIF('Test Cases'!K83:K86,"N/A")>0,"Executed - Pass with N/A","Executed - Pass")))) -> Executed - Pass
A14: REQ-013 | B14: Core pages meet basic accessibility expectations | C14: TS-021 | D14: TC-086 to TC-089 | E14: Medium | F14: =IF(COUNTIF('Test Cases'!K87:K90,"Fail")>0,"Executed - Fail",IF(COUNTIF('Test Cases'!K87:K90,"Blocked")>0,"Executed - Blocked",IF(COUNTIF('Test Cases'!K87:K90,"Not Executed")>0,"Partially Executed",IF(COUNTIF('Test Cases'!K87:K90,"N/A")>0,"Executed - Pass with N/A","Executed - Pass")))) -> Executed - Pass
A15: REQ-014 | B15: Basic black-box security expectations are met | C15: TS-022 | D15: TC-090 to TC-092 | E15: High | F15: =IF(COUNTIF('Test Cases'!K91:K93,"Fail")>0,"Executed - Fail",IF(COUNTIF('Test Cases'!K91:K93,"Blocked")>0,"Executed - Blocked",IF(COUNTIF('Test Cases'!K91:K93,"Not Executed")>0,"Partially Executed",IF(COUNTIF('Test Cases'!K91:K93,"N/A")>0,"Executed - Pass with N/A","Executed - Pass")))) -> Executed - Pass

Sheet Test Data
A1: Data ID | B1: Field | C1: Valid / Invalid | D1: Example | E1: Purpose / Boundary | F1: Sensitive?
A2: TD-001 | B2: Restaurant search | C2: Valid | D2: Pizza | E2: Cuisine search | F2: No
A3: TD-002 | B3: Restaurant search | C3: Valid | D3: Fire And Ice | E3: Restaurant-name search | F3: No
A4: TD-003 | B4: Restaurant search | C4: Invalid/edge | D4: 238 | E4: Whitespace handling | F4: No
A5: TD-004 | B5: Restaurant search | C5: Invalid/edge | D5: @#$%^ | E5: Special-character handling | F5: No
A6: TD-005 | B6: Email | C6: Valid | D6: qa.foodmandu.test@example.com | E6: Format validation only; use disposable inbox if email delivery is tested | F6: No
A7: TD-006 | B7: Email | C7: Invalid | D7: abc@ | E7: Malformed email | F7: No
A8: TD-007 | B8: Email | C8: Invalid | D8: @mail.com | E8: Malformed email | F8: No
A9: TD-008 | B9: Mobile | C9: Valid format | D9: 9801234567 | E9: Nepali mobile-format example; not a real tester number | F9: No
A10: TD-009 | B10: Mobile | C10: Invalid | D10: 980123 | E10: Too short | F10: No
A11: TD-010 | B11: Mobile | C11: Invalid | D11: 98ABCD1234 | E11: Non-numeric | F11: No
A12: TD-011 | B12: Password | C12: Valid example | D12: FoodmanduQA#2026 | E12: Positive format example; do not reuse personal credentials | F12: No
... A16: TD-015 | B16: Search security | C16: Invalid/edge | D16: <script>alert(1)</script> | E16: Safe XSS-oriented encoding check; do not attempt persistence | F16: No

Sheet Exploratory Charters
A1: Charter ID | B1: Mission | C1: Timebox | D1: Focus Areas | E1: Suggested Heuristics | F1: Output
A2: EX-001 | B2: Explore search-to-restaurant discovery as a first-time user | C2: 30 min | D2: Search, filters, no-results, navigation, clarity | E2: Consistency, error states, discoverability | F2: Notes + defects + screenshots
A3: EX-002 | B3: Explore restaurant menu and cart behavior | C3: 30 min | D3: Menu categories, item search, prices, quantity, cart switching | E3: CRUD, boundaries, state transitions | F3: Notes + defects + screenshots
A4: EX-003 | B4: Explore authentication and recovery | C4: 25 min | D4: Login validation, register validation, forgot password, session | E4: Input validation, privacy, security messaging | F4: Notes + defects + screenshots
A5: EX-004 | B5: Explore checkout up to but not including a real order | C5: 30 min | D5: Delivery fields, totals, fees, schedule, confirmation review | E5: Money, data integrity, required fields, accidental actions | F5: Notes + defects + screenshots
A6: EX-005 | B6: Explore mobile responsiveness and accessibility | C6: 30 min | D6: 360/390px widths, keyboard, focus, zoom, labels | E6: Responsive breakpoints, WCAG-oriented smoke | F6: Notes + defects + screenshots
A7: EX-006 | B7: Explore content freshness and consistency | C7: 20 min | D7: Terms, FAQs, delivery fees, footer, restaurant metadata | E7: Consistency, stale content, malformed values | F7: Notes + content defects

Sheet Dashboard
A1: Foodmandu Manual QA Dashboard
A3: Metric | B3: Value | D3: Defect Summary | E3: Value
A4: Total Test Cases | B4: =COUNTA('Test Cases'!A2:A93) -> 92 | D4: Open Defects | E4: =COUNTIF('Defect Log'!G2:G99,"Open") -> 3
A5: Executed (Applicable) | B5: =COUNTIF('Test Cases'!K2:K93,"Pass")+COUNTIF('Test Cases'!K2:K93,"Fail")+COUNTIF('Test Cases'!K2:K93,"Blocked")+COUNTIF('Test Cases'!K2:K93,"Retest") -> 91 | D5: Medium Open | E5: =COUNTIFS('Defect Log'!E2:E99,"Medium",'Defect Log'!G2:G99,"Open") -> 2
A6: Passed | B6: =COUNTIF('Test Cases'!K2:K93,"Pass") -> 89 | D6: Low Open | E6: =COUNTIFS('Defect Log'!E2:E99,"Low",'Defect Log'!G2:G99,"Open") -> 1
A7: Failed | B7: =COUNTIF('Test Cases'!K2:K93,"Fail") -> 2 | D7: Needs Verification | E7: =COUNTIF('Defect Log'!G2:G99,"Needs Browser Verification")+COUNTIF('Defect Log'!G2:G99,"Needs Product Verification") -> 0
A8: Blocked | B8: =COUNTIF('Test Cases'!K2:K93,"Blocked") -> 0 | D8: Not Reproducible | E8: =COUNTIF('Defect Log'!G2:G99,"Not Reproducible") -> 0
A9: N/A | B9: =COUNTIF('Test Cases'!K2:K93,"N/A") -> 1 | D9: Highest Open Severity | E9: Medium
A10: Pass Rate | B10: =IF(B5=0,0,B6/B5) -> 0.97802198
A12: Status | B12: Count
A13: Not Executed | B13: =COUNTIF('Test Cases'!K2:K93,"Not Executed") -> 0
A14: Pass | B14: =COUNTIF('Test Cases'!K2:K93,"Pass") -> 89
A15: Fail | B15: =COUNTIF('Test Cases'!K2:K93,"Fail") -> 2
A16: Blocked | B16: =COUNTIF('Test Cases'!K2:K93,"Blocked") -> 0
A17: Retest | B17: =COUNTIF('Test Cases'!K2:K93,"Retest") -> 0
A18: N/A | B18: =COUNTIF('Test Cases'!K2:K93,"N/A") -> 1
A20: Execution Outcome | B20: Value
A21: Critical/High Failures | B21: 0
A22: Medium Failures | B22: 2
A23: Open Defects | B23: =COUNTIF('Defect Log'!G2:G99,"Open") -> 3
A24: Overall Result | B24: Completed with 2 Medium defects
A28: Workbook Review Notes
A29: Execution reviewed on 2026-08-21. TC-071 is N/A because duplicate final-order submission testing should not be performed on a live operational site without an authorized non-production environment. Failed cases are linked to BUG-001 and BUG-002. OBS-001 was not reproducible; OBS-002 still needs browser verification.
